Workbook

Sheet Documentation
A1: HOUSEHOLD PORTFOLIO ENGINE — SCENARIO DEMO
A3: WHAT THIS WORKBOOK IS
B4: This is a demonstration copy of the Household Portfolio Engine -- a two-bucket, decumulation-phase retirement income strategy built to protect a household from Sequence-of-Returns Risk (SRR). It uses entirely generic example balances and three hardcoded, hypothetical market-return paths (Bear / Bull / Choppy) so you can watch the engine's core mechanic -- the Quarterly Refill Engine's GOOD/POOR trigger -- actually fire in both directions, instead of having to imagine it.
B5: The live version of this workbook is a hand-maintained tracker: real account balances and monthly payments get typed in and the sheet only ever compares today's actual wealth to a target. It never simulates a market move on its own. This demo workbook adds that missing piece -- a simulated household wealth path that evolves year by year under whichever scenario you select -- purely to illustrate how the mechanism behaves under different market conditions.
A7: HOW TO USE THE SCENARIO SELECTOR
B8: On The_Refill_Engine tab, the top-left cell lets you choose Bear, Bull, or Choppy from a dropdown. Bear applies a front-loaded market crash in years 1-2 followed by a recovery -- watch the Quarterly Refill Engine freeze transfers and the G Fund shield draw down on its own. Bull applies steady, consistently strong growth -- the engine should recommend a transfer almost every quarter. Choppy applies small, oscillating returns near the hurdle rate -- GOOD and POOR should alternate unpredictably, which is the case the Safety Anchor is really built for.
B9: Every other input (account balances, COLA, monthly payments) is pre-filled with round, generic numbers so the workbook is fully self-contained -- nothing needs to be typed in to see it work. Feel free to change any pale-yellow cell to explore "what if" variations.
A11: DISCLAIMER
B12: All balances, payments, and the Bear/Bull/Choppy return paths in this workbook are hypothetical and for illustration only. They are not historical market data, a forecast, or investment, tax, or legal advice. Use this workbook to understand the mechanics of the strategy, then work from your own real numbers in the live tracker.
A14: HOW THE FOUR TABS WORK TOGETHER
B15: Documentation (this tab) -- What this demo shows, how to use the scenario selector, the disclaimer above, the color legend, and a glossary. Nothing here feeds any formula.
B16: Variables_And_Log -- The annual COLA/hurdle inputs, the monthly TSP -> checking payment log, and the three hardcoded Bear/Bull/Choppy annual return columns, plus a column that picks out whichever scenario is currently selected.
B17: Account_Tracker -- Generic starting balances for every account as of the beginning of Year 1. Unlike the live tracker, this is not an ongoing snapshot -- it's the starting point that The_Refill_Engine projects forward under the selected scenario.
B18: The_Refill_Engine -- The decision-making tab, plus the scenario selector. The Quarterly Refill Engine table is the headline output. The Annual SRR Hurdle Model below it now also simulates actual household wealth forward year by year under the selected scenario and compares it to the hurdle target, which is what drives GOOD vs. POOR here.
A20: COLOR LEGEND
B21: Pale yellow -- an editable input, pre-filled with an illustrative example value.
B22: White (no fill) -- a formula, or a fixed scenario assumption; please leave it alone.
B23: Ice blue -- a computed summary or headline total.
B24: Green (Emergency Liquidity Protocol only) -- the TSP G Fund shield is active.
B25: Yellow (Emergency Liquidity Protocol only) -- the G Fund is exhausted; drawing from the cash buffer.
B26: Red (Emergency Liquidity Protocol only) -- both cash shields are exhausted; the household is in an emergency-liquidation stage.
A28: GLOSSARY
A29: Term | B29: Definition
A30: COLA | B30: The federal Cost-of-Living Adjustment, applied annually to Social Security/federal retirement benefits.
A31: Hurdle Rate | B31: The minimum real (inflation-adjusted) growth rate the portfolio needs to clear to be considered "on track" -- COLA layered on a fixed real-growth baseline.
A32: W_t / W_q | B32: Total dollar outflows (withdrawals) for a given year (t) or quarter (q).
A33: P_track | B33: The simulated target portfolio value (the hurdle trajectory) that simulated actual wealth is measured against each year.
A34: Scenario | B34: One of three hardcoded, hypothetical annual market-return paths -- Bear, Bull, or Choppy -- selected on The_Refill_Engine tab.
A35: Simulated Actual Household Wealth | B35: This demo's stand-in for real net worth: last year's simulated wealth, grown by the selected scenario's return for the year, less that year's outflows. Compared against P_track to decide GOOD vs. POOR.
A36: SRR | B36: Sequence-of-Returns Risk -- the risk that a downturn early in retirement forces permanent sale of depreciated assets.
A37: TSP G Fund | B37: The federal Thrift Savings Plan's government-securities fund: principal-protected, instantly liquid, and the household's operating cash vault.
A38: Safety Anchor | B38: The G Fund cash buffer this engine tries to maintain. Set as a step function (on The_Refill_Engine): a higher percentage through the SRR "red zone" -- the first several years of retirement -- then a lower one afterward, applied each year to that year's P_track rather than a frozen snapshot.
A39: Red Zone | B39: The first several years of retirement, when a bad sequence of market returns does the most lasting damage to a portfolio. The Safety Anchor holds a higher percentage during this window.
A40: Conduit | B40: A Traditional IRA used as a pass-through for pre-tax rollovers back into the TSP.
A41: Allocation Mix | B41: Each account's share of total household net worth, shown on Account_Tracker.

Sheet Variables_And_Log
A1: HOUSEHOLD VARIABLE LOG — ANNUAL HURDLE INPUTS, MARKET SCENARIOS & MONTHLY TSP → CHECKING PAYMENT LOG (2026-2035)
A2: Date / Year | B2: Actual Federal COLA (C_i) | C2: Rule of Four Hurdle Baseline | D2: Total Annual Hurdle Rate | E2: Total Annual Outflows (W_t) | F2: Jan | G2: Feb | H2: Mar | I2: Apr | J2: May | K2: Jun | L2: Jul | M2: Aug | N2: Sep | O2: Oct | P2: Nov | Q2: Dec | R2: Bear Scenario Annual Return (Illustrative) | S2: Bull Scenario Annual Return (Illustrative) | T2: Choppy Scenario Annual Return (Illustrative) | U2: Selected Scenario Annual Return (This Year)
A3: 2026 | B3: 0.026 | C3: 0.02 | D3: =(1+B3)*(1+C3) | E3: =SUM(F3:Q3) | F3: 4000 | G3: 4000 | H3: 4000 | I3: 4000 | J3: 4000 | K3: 4000 | L3: 4000 | M3: 4000 | N3: 4000 | O3: 4000 | P3: 4000 | Q3: 4000 | R3: -0.35 | S3: 0.1 | T3: 0.09 | U3: =IF('The_Refill_Engine'!$B$1="Bear",R3,IF('The_Refill_Engine'!$B$1="Bull",S3,T3))
A4: 2027 | B4: 0.025 | C4: 0.02 | D4: =(1+B4)*(1+C4) | E4: =SUM(F4:Q4) | F4: 4100 | G4: 4100 | H4: 4100 | I4: 4100 | J4: 4100 | K4: 4100 | L4: 4100 | M4: 4100 | N4: 4100 | O4: 4100 | P4: 4100 | Q4: 4100 | R4: -0.08 | S4: 0.11 | T4: -0.01 | U4: =IF('The_Refill_Engine'!$B$1="Bear",R4,IF('The_Refill_Engine'!$B$1="Bull",S4,T4))
A5: 2028 | B5: 0.024 | C5: 0.02 | D5: =(1+B5)*(1+C5) | E5: =SUM(F5:Q5) | F5: 4200 | G5: 4200 | H5: 4200 | I5: 4200 | J5: 4200 | K5: 4200 | L5: 4200 | M5: 4200 | N5: 4200 | O5: 4200 | P5: 4200 | Q5: 4200 | R5: 0.06 | S5: 0.09 | T5: 0.09 | U5: =IF('The_Refill_Engine'!$B$1="Bear",R5,IF('The_Refill_Engine'!$B$1="Bull",S5,T5))
A6: 2029 | B6: 0.025 | C6: 0.02 | D6: =(1+B6)*(1+C6) | E6: =SUM(F6:Q6) | F6: 4300 | G6: 4300 | H6: 4300 | I6: 4300 | J6: 4300 | K6: 4300 | L6: 4300 | M6: 4300 | N6: 4300 | O6: 4300 | P6: 4300 | Q6: 4300 | R6: 0.09 | S6: 0.12 | T6: -0.01 | U6: =IF('The_Refill_Engine'!$B$1="Bear",R6,IF('The_Refill_Engine'!$B$1="Bull",S6,T6))
A7: 2030 | B7: 0.026 | C7: 0.02 | D7: =(1+B7)*(1+C7) | E7: =SUM(F7:Q7) | F7: 4400 | G7: 4400 | H7: 4400 | I7: 4400 | J7: 4400 | K7: 4400 | L7: 4400 | M7: 4400 | N7: 4400 | O7: 4400 | P7: 4400 | Q7: 4400 | R7: 0.07 | S7: 0.1 | T7: 0.09 | U7: =IF('The_Refill_Engine'!$B$1="Bear",R7,IF('The_Refill_Engine'!$B$1="Bull",S7,T7))
A8: 2031 | B8: 0.025 | C8: 0.02 | D8: =(1+B8)*(1+C8) | E8: =SUM(F8:Q8) | F8: 4500 | G8: 4500 | H8: 4500 | I8: 4500 | J8: 4500 | K8: 4500 | L8: 4500 | M8: 4500 | N8: 4500 | O8: 4500 | P8: 4500 | Q8: 4500 | R8: 0.07 | S8: 0.08 | T8: -0.01 | U8: =IF('The_Refill_Engine'!$B$1="Bear",R8,IF('The_Refill_Engine'!$B$1="Bull",S8,T8))
A9: 2032 | B9: 0.024 | C9: 0.02 | D9: =(1+B9)*(1+C9) | E9: =SUM(F9:Q9) | F9: 4600 | G9: 4600 | H9: 4600 | I9: 4600 | J9: 4600 | K9: 4600 | L9: 4600 | M9: 4600 | N9: 4600 | O9: 4600 | P9: 4600 | Q9: 4600 | R9: 0.07 | S9: 0.11 | T9: 0.09 | U9: =IF('The_Refill_Engine'!$B$1="Bear",R9,IF('The_Refill_Engine'!$B$1="Bull",S9,T9))
A10: 2033 | B10: 0.025 | C10: 0.02 | D10: =(1+B10)*(1+C10) | E10: =SUM(F10:Q10) | F10: 4700 | G10: 4700 | H10: 4700 | I10: 4700 | J10: 4700 | K10: 4700 | L10: 4700 | M10: 4700 | N10: 4700 | O10: 4700 | P10: 4700 | Q10: 4700 | R10: 0.06 | S10: 0.09 | T10: -0.01 | U10: =IF('The_Refill_Engine'!$B$1="Bear",R10,IF('The_Refill_Engine'!$B$1="Bull",S10,T10))
A11: 2034 | B11: 0.026 | C11: 0.02 | D11: =(1+B11)*(1+C11) | E11: =SUM(F11:Q11) | F11: 4800 | G11: 4800 | H11: 4800 | I11: 4800 | J11: 4800 | K11: 4800 | L11: 4800 | M11: 4800 | N11: 4800 | O11: 4800 | P11: 4800 | Q11: 4800 | R11: 0.06 | S11: 0.1 | T11: 0.09 | U11: =IF('The_Refill_Engine'!$B$1="Bear",R11,IF('The_Refill_Engine'!$B$1="Bull",S11,T11))
A12: 2035 | B12: 0.025 | C12: 0.02 | D12: =(1+B12)*(1+C12) | E12: =SUM(F12:Q12) | F12: 4900 | G12: 4900 | H12: 4900 | I12: 4900 | J12: 4900 | K12: 4900 | L12: 4900 | M12: 4900 | N12: 4900 | O12: 4900 | P12: 4900 | Q12: 4900 | R12: 0.06 | S12: 0.09 | T12: -0.01 | U12: =IF('The_Refill_Engine'!$B$1="Bear",R12,IF('The_Refill_Engine'!$B$1="Bull",S12,T12))
A14: Notes: COLA, monthly payments, and the account balances on Account_Tracker are all generic illustrative numbers -- change any pale-yellow cell to explore a variation. The Bear/Bull/Choppy columns are fixed scenario definitions (hypothetical, not historical); the selector that picks among them lives on The_Refill_Engine tab.
A15: Legend: pale-yellow cells are yours to type into (pre-filled here with illustrative example numbers); white cells hold formulas or fixed scenario assumptions -- please don't overwrite them.

Sheet Account_Tracker
A1: Asset Pool | B1: Custodian / Platform | C1: Starting Balance (Beginning of Year 1) | D1: Allocation Mix
A2: Your Pre-Tax Account | B2: TSP G Fund | C2: 100000 | D2: =C2/$C$9
A3: Your Conversion Conduit | B3: Private Traditional IRA | C3: 100000 | D3: =C3/$C$9
A4: Your Tax-Free Growth | B4: Private Roth IRA | C4: 100000 | D4: =C4/$C$9
A5: Spouse's Tax-Free Growth | B5: Private Roth IRA | C5: 100000 | D5: =C5/$C$9
A6: Spouse's Safe Pre-Tax Account | B6: Current Employer 403b (Active + Reverse Rollover) | C6: 100000 | D6: =C6/$C$9
A7: Spouse's Conversion Conduit | B7: Private Traditional IRA | C7: 100000 | D7: =C7/$C$9
A8: Short-Term Liquidity | B8: Merrill Edge Cash Buffer | C8: 100000 | D8: =C8/$C$9
A9: Total Household Net Worth | C9: =SUM(C2:C8) | D9: =C9/C9
A10: Note: unlike the live tracker, these are not an ongoing snapshot -- they're the starting point (beginning of Year 1) that The_Refill_Engine projects forward under whichever scenario is selected.
A11: Legend: pale-yellow cells are yours to type into (pre-filled here with illustrative example numbers); white cells hold formulas or fixed scenario assumptions -- please don't overwrite them.

Sheet The_Refill_Engine
A1: Scenario Selector | B1: Bear | C1: ← choose Bear / Bull / Choppy to see the engine react to each hardcoded market path
A3: Starting Household Wealth (Year 1 Opening) | B3: ='Account_Tracker'!$C$9
A4: Retirement Start Year | B4: 2026
A5: Age at Retirement Start | B5: 63
A6: Red Zone Length (Years) | B6: 10
A7: Red Zone Target % (elevated, early retirement) | B7: 0.35
A8: Post-Red-Zone Target % (steady state) | B8: 0.25
A9: Current Safety Anchor % | B9: =IF(YEAR(TODAY())-B4<B6,B7,B8)
A10: Target Safety Anchor Balance (Year 1 Opening) | B10: =B3*B9
A11: Sequence-of-Returns-Risk (SRR) Shield: this engine uses a step function, not a flat percentage. SRR is concentrated in the first years of retirement (the "red zone"), when a bad sequence does the most damage; research supports holding a larger safety anchor through that window, then a smaller one afterward. Each year's actual target -- Red Zone % while Year < Retirement Start Year + Red-Zone-Length, Post-Red-Zone % after -- is computed per-year in the Annual SRR Hurdle Model below and drives the Quarterly Refill Engine's 'Target Safety Anchor Balance (This Year)' column, scaled against that year's simulated wealth path, not a value frozen at Year 1. Row 10 above is only a Year-1 snapshot for quick reference. In this demo, GOOD/POOR below is driven by the Scenario Selector above, not a live account snapshot.
A13: THE QUARTERLY REFILL ENGINE — PRIMARY OUTPUT: RECOMMENDED TSP TOP-UP TRANSFER
A14: Year | B14: Quarter | C14: Quarterly Outflow (W_q) | D14: Annual Performance Signal | E14: G Fund Balance (Start of Qtr) | F14: Recommended Transfer This Quarter | G14: Actual Transferred (Log It Here) | H14: G Fund Balance (End of Qtr, Projected) | I14: Target Safety Anchor Balance (This Year)
A15: 2026 | B15: Q1 | C15: =SUM('Variables_And_Log'!F3:H3) | D15: =G59 | E15: ='Account_Tracker'!$C$2 | F15: =IF(ISNUMBER(SEARCH("GOOD",D15)),MAX(0,I15-E15),0) | H15: =MAX(0,E15-C15+IF(G15="",F15,G15)) | I15: =H59*D59
A16: 2026 | B16: Q2 | C16: =SUM('Variables_And_Log'!I3:K3) | D16: =G59 | E16: =H15 | F16: =IF(ISNUMBER(SEARCH("GOOD",D16)),MAX(0,I16-E16),0) | H16: =MAX(0,E16-C16+IF(G16="",F16,G16)) | I16: =H59*D59
A17: 2026 | B17: Q3 | C17: =SUM('Variables_And_Log'!L3:N3) | D17: =G59 | E17: =H16 | F17: =IF(ISNUMBER(SEARCH("GOOD",D17)),MAX(0,I17-E17),0) | H17: =MAX(0,E17-C17+IF(G17="",F17,G17)) | I17: =H59*D59
A18: 2026 | B18: Q4 | C18: =SUM('Variables_And_Log'!O3:Q3) | D18: =G59 | E18: =H17 | F18: =IF(ISNUMBER(SEARCH("GOOD",D18)),MAX(0,I18-E18),0) | H18: =MAX(0,E18-C18+IF(G18="",F18,G18)) | I18: =H59*D59
A19: 2027 | B19: Q1 | C19: =SUM('Variables_And_Log'!F4:H4) | D19: =G60 | E19: =H18 | F19: =IF(ISNUMBER(SEARCH("GOOD",D19)),MAX(0,I19-E19),0) | H19: =MAX(0,E19-C19+IF(G19="",F19,G19)) | I19: =H60*D60
A20: 2027 | B20: Q2 | C20: =SUM('Variables_And_Log'!I4:K4) | D20: =G60 | E20: =H19 | F20: =IF(ISNUMBER(SEARCH("GOOD",D20)),MAX(0,I20-E20),0) | H20: =MAX(0,E20-C20+IF(G20="",F20,G20)) | I20: =H60*D60
A21: 2027 | B21: Q3 | C21: =SUM('Variables_And_Log'!L4:N4) | D21: =G60 | E21: =H20 | F21: =IF(ISNUMBER(SEARCH("GOOD",D21)),MAX(0,I21-E21),0) | H21: =MAX(0,E21-C21+IF(G21="",F21,G21)) | I21: =H60*D60
A22: 2027 | B22: Q4 | C22: =SUM('Variables_And_Log'!O4:Q4) | D22: =G60 | E22: =H21 | F22: =IF(ISNUMBER(SEARCH("GOOD",D22)),MAX(0,I22-E22),0) | H22: =MAX(0,E22-C22+IF(G22="",F22,G22)) | I22: =H60*D60
A23: 2028 | B23: Q1 | C23: =SUM('Variables_And_Log'!F5:H5) | D23: =G61 | E23: =H22 | F23: =IF(ISNUMBER(SEARCH("GOOD",D23)),MAX(0,I23-E23),0) | H23: =MAX(0,E23-C23+IF(G23="",F23,G23)) | I23: =H61*D61
A24: 2028 | B24: Q2 | C24: =SUM('Variables_And_Log'!I5:K5) | D24: =G61 | E24: =H23 | F24: =IF(ISNUMBER(SEARCH("GOOD",D24)),MAX(0,I24-E24),0) | H24: =MAX(0,E24-C24+IF(G24="",F24,G24)) | I24: =H61*D61
A25: 2028 | B25: Q3 | C25: =SUM('Variables_And_Log'!L5:N5) | D25: =G61 | E25: =H24 | F25: =IF(ISNUMBER(SEARCH("GOOD",D25)),MAX(0,I25-E25),0) | H25: =MAX(0,E25-C25+IF(G25="",F25,G25)) | I25: =H61*D61
A26: 2028 | B26: Q4 | C26: =SUM('Variables_And_Log'!O5:Q5) | D26: =G61 | E26: =H25 | F26: =IF(ISNUMBER(SEARCH("GOOD",D26)),MAX(0,I26-E26),0) | H26: =MAX(0,E26-C26+IF(G26="",F26,G26)) | I26: =H61*D61
A27: 2029 | B27: Q1 | C27: =SUM('Variables_And_Log'!F6:H6) | D27: =G62 | E27: =H26 | F27: =IF(ISNUMBER(SEARCH("GOOD",D27)),MAX(0,I27-E27),0) | H27: =MAX(0,E27-C27+IF(G27="",F27,G27)) | I27: =H62*D62
A28: 2029 | B28: Q2 | C28: =SUM('Variables_And_Log'!I6:K6) | D28: =G62 | E28: =H27 | F28: =IF(ISNUMBER(SEARCH("GOOD",D28)),MAX(0,I28-E28),0) | H28: =MAX(0,E28-C28+IF(G28="",F28,G28)) | I28: =H62*D62
A29: 2029 | B29: Q3 | C29: =SUM('Variables_And_Log'!L6:N6) | D29: =G62 | E29: =H28 | F29: =IF(ISNUMBER(SEARCH("GOOD",D29)),MAX(0,I29-E29),0) | H29: =MAX(0,E29-C29+IF(G29="",F29,G29)) | I29: =H62*D62
A30: 2029 | B30: Q4 | C30: =SUM('Variables_And_Log'!O6:Q6) | D30: =G62 | E30: =H29 | F30: =IF(ISNUMBER(SEARCH("GOOD",D30)),MAX(0,I30-E30),0) | H30: =MAX(0,E30-C30+IF(G30="",F30,G30)) | I30: =H62*D62
A31: 2030 | B31: Q1 | C31: =SUM('Variables_And_Log'!F7:H7) | D31: =G63 | E31: =H30 | F31: =IF(ISNUMBER(SEARCH("GOOD",D31)),MAX(0,I31-E31),0) | H31: =MAX(0,E31-C31+IF(G31="",F31,G31)) | I31: =H63*D63
A32: 2030 | B32: Q2 | C32: =SUM('Variables_And_Log'!I7:K7) | D32: =G63 | E32: =H31 | F32: =IF(ISNUMBER(SEARCH("GOOD",D32)),MAX(0,I32-E32),0) | H32: =MAX(0,E32-C32+IF(G32="",F32,G32)) | I32: =H63*D63
A33: 2030 | B33: Q3 | C33: =SUM('Variables_And_Log'!L7:N7) | D33: =G63 | E33: =H32 | F33: =IF(ISNUMBER(SEARCH("GOOD",D33)),MAX(0,I33-E33),0) | H33: =MAX(0,E33-C33+IF(G33="",F33,G33)) | I33: =H63*D63
A34: 2030 | B34: Q4 | C34: =SUM('Variables_And_Log'!O7:Q7) | D34: =G63 | E34: =H33 | F34: =IF(ISNUMBER(SEARCH("GOOD",D34)),MAX(0,I34-E34),0) | H34: =MAX(0,E34-C34+IF(G34="",F34,G34)) | I34: =H63*D63
A35: 2031 | B35: Q1 | C35: =SUM('Variables_And_Log'!F8:H8) | D35: =G64 | E35: =H34 | F35: =IF(ISNUMBER(SEARCH("GOOD",D35)),MAX(0,I35-E35),0) | H35: =MAX(0,E35-C35+IF(G35="",F35,G35)) | I35: =H64*D64
A36: 2031 | B36: Q2 | C36: =SUM('Variables_And_Log'!I8:K8) | D36: =G64 | E36: =H35 | F36: =IF(ISNUMBER(SEARCH("GOOD",D36)),MAX(0,I36-E36),0) | H36: =MAX(0,E36-C36+IF(G36="",F36,G36)) | I36: =H64*D64
A37: 2031 | B37: Q3 | C37: =SUM('Variables_And_Log'!L8:N8) | D37: =G64 | E37: =H36 | F37: =IF(ISNUMBER(SEARCH("GOOD",D37)),MAX(0,I37-E37),0) | H37: =MAX(0,E37-C37+IF(G37="",F37,G37)) | I37: =H64*D64
A38: 2031 | B38: Q4 | C38: =SUM('Variables_And_Log'!O8:Q8) | D38: =G64 | E38: =H37 | F38: =IF(ISNUMBER(SEARCH("GOOD",D38)),MAX(0,I38-E38),0) | H38: =MAX(0,E38-C38+IF(G38="",F38,G38)) | I38: =H64*D64
A39: 2032 | B39: Q1 | C39: =SUM('Variables_And_Log'!F9:H9) | D39: =G65 | E39: =H38 | F39: =IF(ISNUMBER(SEARCH("GOOD",D39)),MAX(0,I39-E39),0) | H39: =MAX(0,E39-C39+IF(G39="",F39,G39)) | I39: =H65*D65
A40: 2032 | B40: Q2 | C40: =SUM('Variables_And_Log'!I9:K9) | D40: =G65 | E40: =H39 | F40: =IF(ISNUMBER(SEARCH("GOOD",D40)),MAX(0,I40-E40),0) | H40: =MAX(0,E40-C40+IF(G40="",F40,G40)) | I40: =H65*D65
A41: 2032 | B41: Q3 | C41: =SUM('Variables_And_Log'!L9:N9) | D41: =G65 | E41: =H40 | F41: =IF(ISNUMBER(SEARCH("GOOD",D41)),MAX(0,I41-E41),0) | H41: =MAX(0,E41-C41+IF(G41="",F41,G41)) | I41: =H65*D65
A42: 2032 | B42: Q4 | C42: =SUM('Variables_And_Log'!O9:Q9) | D42: =G65 | E42: =H41 | F42: =IF(ISNUMBER(SEARCH("GOOD",D42)),MAX(0,I42-E42),0) | H42: =MAX(0,E42-C42+IF(G42="",F42,G42)) | I42: =H65*D65
...
